Workbook

Sheet Gantt
A1: Rozpoczęcie projektu 01.07.2027 r. | N1: Data początkowa konkursu: 07.08.2026 r.
A2: Zakończenie projektu 31.11.2030 r. | N2: Data końcowa konkursu: 16.10.2026, godz. 16.00.
A4: Wykres Gantta
A5: Kategoria | C5: Nr zadania | D5: Nazwa zadania | E5: Konsorcjant odpowiedzialny za realizację zadania | F5: Okres realizacji | H5: 2027 | T5: 2028 | AF5: 2029 | AR5: 2030
G6: Kalendarz | H6: 1 | I6: 2 | J6: 3 | K6: 4 | L6: 5 | M6: 6 | N6: 7 | O6: 8 | P6: 9 | Q6: 10 | R6: 11 | S6: 12 | T6: 1 | U6: 2 | V6: 3 | W6: 4 | X6: 5 | Y6: 6 | Z6: 7 | AA6: 8 | AB6: 9 | AC6: 10 | AD6: 11 | AE6: 12 | AF6: 1 | AG6: 2 | AH6: 3 | AI6: 4 | AJ6: 5 | AK6: 6 | AL6: 7 | AM6: 8 | AN6: 9 | AO6: 10 | AP6: 11 | AQ6: 12 | AR6: 1 | AS6: 2 | AT6: 3 | AU6: 4 | AV6: 5 | AW6: 6 | AX6: 7 | AY6: 8 | AZ6: 9 | BA6: 10 | BB6: 11 | BC6: 12
A7: badania przemysłowe/prace rozwojowe | G7: nr miesiąca PROJEKTU | H7: 1 | I7: 2 | J7: 3 | K7: 4 | L7: 5 | M7: 6 | N7: 7 | O7: 8 | P7: 9 | Q7: 10 | R7: 11 | S7: 12 | T7: 13 | U7: 14 | V7: 15 | W7: 16 | X7: 17 | Y7: 18 | Z7: 19 | AA7: 20 | AB7: 21 | AC7: 22 | AD7: 23 | AE7: 24 | AF7: 25 | AG7: 26 | AH7: 27 | AI7: 28 | AJ7: 29 | AK7: 30 | AL7: 31 | AM7: 32 | AN7: 33 | AO7: 34 | AP7: 35 | AQ7: 36 | AR7: 37 | AS7: 38 | AT7: 39 | AU7: 40 | AV7: 41 | AW7: 42 | AX7: 43 | AY7: 44 | AZ7: 45 | BA7: 46 | BB7: 47 | BC7: 48
A8: Badania przemysłowe | C8: 1 | N8: 1 | O8: 2 | P8: 3 | Q8: 4 | R8: 5 | S8: 6 | T8: 7 | U8: 8 | V8: 9 | W8: 10 | X8: 11 | Y8: 12 | Z8: 13 | AA8: 14 | AB8: 15 | AC8: 16 | AD8: 17 | AE8: 18 | AF8: 19 | AG8: 20 | AH8: 21 | AI8: 22 | AJ8: 23 | AK8: 24 | AL8: 25 | AM8: 26 | AN8: 27 | AO8: 28 | AP8: 29 | AQ8: 30 | AR8: 31 | AS8: 32 | AT8: 33 | AU8: 34 | AV8: 35 | AW8: 36 | AX8: 37 | AY8: 38 | AZ8: 39 | BA8: 40 | BB8: 41 | BC8: 42
A9: Badania przemysłowe | C9: 2 | T9: 7 | U9: 8 | V9: 9 | W9: 10 | X9: 11 | Y9: 12 | Z9: 13 | AA9: 14 | AB9: 15 | AC9: 16 | AD9: 17 | AE9: 18 | AF9: 19 | AG9: 20 | AH9: 21 | AI9: 22 | AJ9: 23 | AK9: 24 | AL9: 25 | AM9: 26 | AN9: 27 | AO9: 28 | AP9: 29 | AQ9: 30
A10: Badania przemysłowe | C10: 3 | AM10: 1 | AN10: 2 | AO10: 3 | AP10: 4 | AQ10: 5 | AR10: 6 | AS10: 7 | AT10: 8 | AU10: 9 | AV10: 10 | AW10: 11 | AX10: 12 | AY10: 13 | AZ10: 14 | BA10: 15 | BB10: 16
A11: Prace rozwojowe | C11: 4 | AU11: 1 | AV11: 2 | AW11: 3 | AX11: 4 | AY11: 5 | AZ11: 6 | BA11: 7 | BB11: 8
A12: Koszty pośrednie | C12: 5 | H12: 1 | I12: 2 | J12: 3 | K12: 4 | L12: 5 | M12: 6 | N12: 7 | O12: 8 | P12: 9 | Q12: 10 | R12: 11 | S12: 12 | T12: 13 | U12: 14 | V12: 15 | W12: 16 | X12: 17 | Y12: 18 | Z12: 19 | AA12: 20 | AB12: 21 | AC12: 22 | AD12: 23 | AE12: 24 | AF12: 25 | AG12: 26 | AH12: 27 | AI12: 28 | AJ12: 29 | AK12: 30 | AL12: 31 | AM12: 32 | AN12: 33 | AO12: 34 | AP12: 35 | AQ12: 36 | AR12: 37 | AS12: 38 | AT12: 39 | AU12: 40 | AV12: 41 | AW12: 42 | AX12: 43 | AY12: 44 | AZ12: 45 | BA12: 46 | BB12: 47
A14: w projekcie muszą być wykazane prace rozwojowe lub badania przemysłowe + prace rozwojowe

Sheet Ponowne złożenie
A1: Wniosek dotyczący projektu składany jest ponownie
A2: Numer wcześniej składanego wniosku
A3: Tytuł wcześniej składanego projektu
A4: Opis zmian (max. 1000 znaków) | O4: =LEN(F4) -> 0

Sheet Część ogólna
A1: Tytuł projektu max. 150 znaków
A2: Wpisz pełny tytuł odzwierciedlający przedmiot projektu. Tytuł nie może być nadmiernie rozbudowany.
S3: =LEN(A3) -> 0
A4: Data rozpoczęcia realizacji projektu
A5: Rozpoczęcie realizacji projektu może nastąpić najwcześniej po dniu złożenia wniosku
A7: Data zakończenia realizacji projektu
A8: Zrealizowanie pełnego zakresu rzeczowego i finansowego projektu wraz ze złożeniem wniosku o płatność końcową musi nastąpić najpóźniej do dnia 31 grudnia 2030 r.
A10: Opis projektu (4000 znaków)
A11: Opisz przedmiot oraz zakres projektu i jego rezultaty. Opis powinien być maksymalnie konkretny i precyzyjny, należy unikać cytowania opisu z kryterium Istota modułu w poszczególnych modułach.
S12: =LEN(A12) -> 0
A13: Uzasadnienie wybranego KIS, w który wpisuje się projekt (2000 znaków)
A14: KIS 1. ZDROWE SPOŁECZEŃSTWO, Obszar KIS: I. BADANIA I ROZWÓJ PRODUKTÓW LECZNICZYCH
S15: =LEN(A15) -> 0
A16: INFORMACJA O CZŁONKACH KONSORCJUM
A17: Rola w konsorcjum (należy wybrać: Lider konsorcjum/Konsorcjant) | H17: Lider konsorcjum
A18: Nazwa 1000 znaków | S18: =LEN(H18) -> 0
A19: Nazwa skrócona 400 znaków | S19: =LEN(H19) -> 0
A20: Data rozpoczęcia działalności zgodnie z dokumentem rejestrowym rrrr/mm/dd
A21: Rodzaj podmiotu (należy wybrać: przedsiębiorstwo/organizacja badawcza) | H21: przedsiębiorstwo
A22: Forma prawna | H22: spółki z ograniczoną odpowiedzialnością
A23: Forma własności | H23: krajowe osoby fizyczne
A24: Wielkość przedsiębiorstwa | H24: małe
A25: NIP
A26: REGON
A27: Numer w Krajowym Rejestrze Sądowym 10 cyfr
A28: Inny rejestr (jeśli dotyczy) | H28: Nie dotyczy
A29: Numer kodu PKD przeważającej działalności | H29: 72.11.Z Badania naukowe i prace rozwojowe w dziedzinie biotechnologii
A30: Możliwość odzyskania VAT (należy wybrać: tak, nie, częściowo) | H30: Tak
A31: Uzasadnienie braku możliwości odzyskania VAT 1000 znaków | S31: =LEN(H31) -> 0
A32: Adres
A33: Województwo
A34: Powiat
A35: Gmina
A36: Miejscowość
A37: Kod pocztowy
A38: Ulica (jeśli dotyczy)
A39: Nr budynku
A40: Nr lokalu (jeśli dotyczy)
A41: Telefon
A42: Adres e-mail
...

Sheet Moduł B+R
A2: 1 ISTOTA MODUŁU
A3: Rodzaj prac
A4: Wybierz jaki rodzaj prac będzie realizowany w ramach modułu. Pamiętaj, że przedmiotem modułu może być przeprowadzenie badań przemysłowych i prac rozwojowych albo tylko prac rozwojowych.
A5: badania przemysłowe
A6: prace rozwojowe
A7: Cel projektu (limit 4000 znaków)
A8: Przedstaw krótko cel, który planowany jest do osiągnięcia w wyniku realizacji modułu. Jeśli realizujesz moduł z konsorcjantem, uzasadnij, że zadania zaplanowane do realizacji w module składają się na wspólne przedsięwzięcie o sprecyzowanym charakterze i wspólnym celu, niemożliwym lub znacznie utrudnionym do osiągnięcia bez udziału tego konsorcjanta.
T9: =LEN(A9) -> 0
A10: Problem badawczy/technologiczny (limit 10000 znaków)
A11: Zidentyfikuj problem badawczy/technologiczny, którego dotyczą planowane w module badania przemysłowe i prace rozwojowe albo tylko prace rozwojowe. Opisz problem badawczy/technologiczny w kontekście określonej potrzeby społecznej/ gospodarczej/ rynkowej. Rozwiązanie, które będzie osiągnięte w wyniku realizacji badań przemysłowych i prac rozwojowych (lub tylko prac rozwojowych) powinno stanowić innowację produktową lub innowację w procesie biznesowym (w zakresie produkcji wyrobów i usług). Opisz stan wiedzy na świecie na temat zidentyfikowanego problemu badawczego/technologicznego.
T12: =LEN(A12) -> 0
A13: Metoda badawcza (limit 2000 znaków)
A14: Przedstaw założony sposób rozwiązania problemu badawczego/technologicznego (przyjętą koncepcję), który ma doprowadzić do wypracowania oczekiwanego rezultatu modułu, jak również przesłanki świadczące o tym, że przyjęta koncepcja może doprowadzić do rozwiązania tego problemu. Określ metody, techniki, narzędzia badawcze oraz uzasadnij ich wybór (celowość, skuteczność, niezawodność, ekonomiczność) w odniesieniu do celu modułu oraz opisz logikę zaplanowanych prac, wskaż powiązania pomiędzy poszczególnymi zadaniami i uzasadnij kolejność ich realizacji. Można dodać załącznik w formacie graficznym (JPEG, BMP, GIF, PNG) np. schemat blokowy, wykres czy tabelę. Załącznik nie może jednak stanowić rozszerzenia opisu. Załącznik nie może przekraczać 2 stron A4.
T15: =LEN(A15) -> 0
A16: Rodzaj innowacji w skali polskiego rynku
A17: Wybierz z listy rozwijanej rodzaj innowacji, którą przewidziałeś w module (możliwe jest zaznaczenie obu opcji) • Innowacja produktowa • Innowacja w procesie biznesowym
A18: Innowacja produktowa
A19: Innowacyjność produktu lub procesu biznesowego
A20: Rodzaj innowacji w skali rynku polskiego
A21: Innowacja produktowa
A22: Nazwa produktu / procesu biznesowego (limit 100 znaków)
T23: =LEN(A23) -> 0
A24: Czy produkt / proces biznesowy będzie wdrażany w ramach modułu „Wdrożenie innowacji” (TAK/NIE)
A26: Opis innowacji produktowej / innowacji w procesie biznesowym (limit 12 000 znaków)
A27: Wykaż, że rezultat modułu tj. produkt (wyrób lub usługa) lub proces biznesowy dotyczący funkcji działalności przedsiębiorstwa (w zakresie produkcji wyrobów lub usług), charakteryzuje się nowością co najmniej w skali polskiego rynku, tzn. znacząco różni się od produktów (wyrobów lub usług) lub procesów biznesowych dostępnych na polskim rynku w kontekście posiadanych przez niego nowych cech, funkcjonalności. Opisz te najważniejsze cechy lub funkcjonalności, decydujące o jego przewadze względem aktualnej oferty na rynku (własnej oferty Lidera konsorcjum i, jeśli dotyczy, konsorcjanta – jeśli jest najlepsza na rynku lub konkurencyjnej). Wskaż produkt/proces, do którego się porównujesz (w przypadku produktu podaj jego nazwę i producenta, w przypadku procesu podaj jego nazwę i wskaż gdzie jest stosowany). Ponadto wykaż, że produkt/proces lepiej zaspokoi potrzebę odbiorcy lub zaadresuje wyzwanie niż rozwiązania dotychczasowe/konkurencyjne. Pamiętaj, że cechy lub funkcjonalności świadczące o innowacyjności co najmniej na poziomie kraju muszą wynikać z zaplanowanych w module prac B+R.
T28: =LEN(A28) -> 0
A31: Wskaźniki dotyczące cech/funkcjonalności innowacji produktowej/innowacji w procesie biznesowym
A32: lista wielokrotnego wyboru wskaźników
A33: Wskaźnik 1: Nazwa cechy/funkcjonalności: Wartość bazowa: Wartość docelowa: Jednostka: Produkt referencyjny: Korzyść/przewaga: Metodologia szacowania: Weryfikacja: Wskaźnik 2: Wskaźnik 1: Nazwa cechy/funkcjonalności: Wartość bazowa: Wartość docelowa: Jednostka: Produkt referencyjny: Korzyść/przewaga: Metodologia szacowania: Weryfikacja:
A34: 2 ZAPOTRZEBOWANIE RYNKOWE I OPŁACALNOŚĆ WDROŻENIA MODUŁU B+R | T34: =LEN(A36) -> 0
A35: Zapotrzebowanie rynkowe na rezultat projektu (max. 10 000 znaków)
A37: Konkurencyjność - Innowacja produktowa
A38: Rynek docelowy dla innowacji produktowej oraz zapotrzebowanie rynkowe na produkt (limit 6000 znaków)
A40: GRUPA DOCELOWA WIELKOŚĆ RYNKU I ZAPOTRZEBOWANIE TRENDY CHŁONNOŚĆ, NASYCENIE I POKRYCIE POPYTU . PORÓWNANIE Z KONKURENCJĄ NOWI GRACZE UDZIAŁ W RYNKU I UPLASOWANIE | T40: =LEN(A40) -> 167
A41: Plan wprowadzenia rezultatu modułu na rynek – innowacja produktowa (limit 6000 znaków)
A42: Opisz jak zamierzasz wprowadzić na rynek produkt będący wynikiem realizacji modułu. Opisz, w jaki sposób zorganizowana będzie dystrybucja i sprzedaż produktu będącego rezultatem modułu. Umieść informację o miejscu sprzedaży, np. sklepy detaliczne, hurtownie, supermarkety, sprzedaż w siedzibie producenta, sprzedaż za pośrednictwem Internetu itp. Analogicznie opisz plan gdy wprowadzenie rezultatu na rynek przyjmie formę udzielenia licencji lub sprzedaży praw do wyników.
T43: =LEN(A43) -> 0
A45: Konkurencyjność - Innowacja w procesie biznesowym
A47: Wpływ innowacji w procesie biznesowym na cykl produkcyjny (limit 3000 znaków)
A48: Wskaż wpływ innowacji w procesie biznesowym będącej efektem realizacji modułu, na cykl produkcyjny Lidera konsorcjum/konsorcjanta.
...

Sheet BUDŻET - zad. 1
B2: BUDŻET
B3: Dofinansowanie w projektach będzie miało charakter dotacji i będzie udzielane w formie pomocy publicznej i pomocy de minimis dla lidera konsorcjum oraz pozostałych konsorcjantów niebędących organizacją badawczą. Minimalna wysokość wydatków kwalifikowalnych wynosi 3 mln zł. Łączna kwota wnioskowanego dofinansowania nie może przekroczyć 140 mln zł na cały projekt. Organizacje badawcze w ramach swojej działalności niegospodarczej uzyskują wsparcie bez pomocy publicznej.
B7: Tytuł zadania:
B8: Zadanie 1
B9: Wynagrodzenia - Personel projektu
B10: W ramach kategorii kwalifikowalne jest wyłącznie wynagrodzenie personelu projektu badawczo-rozwojowego będącego przedmiotem modułu B+R - pracowników kadry naukowo-badawczej W przypadku wykonywania przez dany personel jakichkolwiek zadań związanych z zarządzaniem, nadzorem lub koordynacją projektem badawczo-rozwojowym będącym przedmiotem modułu B+R lub zarządzeniem modułem B+R lub zarządzaniem projektem (składającym się także z innych modułów niż moduł B+R), koszt jego wynagrodzenia jest niekwalifikowalny w kategorii Personel projektu. Koszt wynagrodzenia takich osób (np. kierownika zarządzającego modułem, kierownika modułu B+R), niezależnie od wymiaru zaangażowania w czynności zarządcze i łączenie ich z zadaniami badawczymi, stanowi w całości wydatek kwalifikowalny w kategorii Koszty pośrednie (ogólne).
B11: Lp. | C11: Nazwa wydatku | D11: Wydatki ogółem | E11: Wydatki kwalifikowalne | F11: VAT | G11: Dofinansowanie | H11: Uzasadnienie kosztu max. 1500 znaków | I11: Metody szacowania max. 1500 znaków
B12: 1 | C12: Wynagrodzenie: Stanowisko badawcze nr 1 w projekcie (nazwa) | D12: 0 | E12: =D12 -> 0 | F12: 0 | G12: =E12*80% -> 0 | H12: zgodnie z Przewodnikiem kwalifikowalności wydatków należy wskazać sposób zaangażowania pracownika np.. Umowa o pracę, kontrakt B2B, dodatki zadaniowe, oddelegowanie, umowy zlecenia). Kwoty należy podać jako pełny koszt (tzw. brutto brutto) z uwzględnieniem wynagrodzenia zasadnicznego + składek po stronie pracownika i pracodwacy wraz z okresem zaangażowania pracownika do realizacji zadania (wymiar etatu, zaangażowanie godzinowe), należy pokazać kalkulację wydatku projektowego. Łączne zaangażowanie zawodowe personelu projektu w realizację wszystkich projektów finansowanych z funduszy UE oraz działań finansowanych z innych źródeł, w tym środków własnych lidera konsorcjum lub konsorcjanta i innych podmiotów (niezależnie od formy zaangażowania) nie przekracza 276 godzin miesięcznie | K12: Podatek VAT co do zasady stanowi wydatek niekwalifikowalny w projekcie. Podatek VAT może stanowić wydatek kwalifikowalny dla danego członka konsorcjum w ramach projektu tylko wtedy, gdy danemu członkowi konsorcjum, zgodnie z obowiązującym prawodawstwem krajowym, nie przysługuje prawo do obniżenia kwoty podatku należnego o kwotę podatku naliczonego lub ubiegania się o zwrot podatku VAT. Posiadanie przez danego członka konsorcjum wyżej wymienionego prawa (potencjalnej prawnej możliwości) wyklucza uznanie wydatku za kwalifikowalny, nawet jeśli faktycznie zwrot nie nastąpił, np. ze względu na niepodjęcie przez danego członka konsorcjum czynności zmierzających do realizacji tego prawa. Ocena kwalifikowalności VAT jest dokonywana z punktu widzenia każdego z członków konsorcjum z osobna – z uwzględnieniem ich prawa do odzyskania VAT. Dla projektów z planowaną komercjalizacją rozumianą jako przychód zalecaną formą jest wybór VAT jak kosztu niekwalifikowalnego, niemniej jednak decyzja w tym zakresie leży po stronie danego podmiotu będącego członkiem konsorcjum.
B13: 2 | D13: 0 | E13: =D13 -> 0 | F13: 0 | G13: =E13*80% -> 0
B14: 3 | D14: 0 | E14: =D14 -> 0 | F14: 0 | G14: =E14*80% -> 0
B15: 4 | D15: 0 | E15: =D15 -> 0 | F15: 0 | G15: =E15*80% -> 0
B16: 5 | D16: 0 | E16: =D16 -> 0 | F16: 0 | G16: =E16*80% -> 0
B17: 6 | D17: 0 | E17: =D17 -> 0 | F17: 0 | G17: =E17*80% -> 0
B18: 7 | D18: 0 | E18: =D18 -> 0 | F18: 0 | G18: =E18*80% -> 0
B19: 8 | D19: 0 | E19: =D19 -> 0 | F19: 0 | G19: =E19*80% -> 0
B20: 9 | D20: 0 | E20: =D20 -> 0 | F20: 0 | G20: =E20*80% -> 0
B21: 10 | D21: 0 | E21: =D21 -> 0 | F21: 0 | G21: =E21*80% -> 0
B22: 11 | D22: 0 | E22: =D22 -> 0 | F22: 0 | G22: =E22*80% -> 0
B23: 12 | D23: 0 | E23: =D23 -> 0 | F23: 0 | G23: =E23*80% -> 0
B24: 13 | D24: 0 | E24: =D24 -> 0 | F24: 0 | G24: =E24*80% -> 0
B25: 14 | D25: 0 | E25: =D25 -> 0 | F25: 0 | G25: =E25*80% -> 0
B26: SUMA WYNAGRODZENIA: | D26: =SUM(D12:D25) -> 0 | E26: =SUM(E12:E25) -> 0 | F26: =SUM(F12:F25) -> 0 | G26: =SUM(G12:G25) -> 0
B27: Usługi zewnętrzne (podwykonawstwo)
B28: W ramach kategorii usługi zewnętrzne (podwykonawstwo) kwalifikowalne są koszty badań wykonywanych na podstawie umowy oraz koszty doradztwa i równorzędnych usług wykorzystywanych wyłącznie na potrzeby projektu badawczo-rozwojowego. Podwykonawstwem nie są czynności pomocnicze niezbędne do wykonania zadań projektowych, takie jak usługi prawne, księgowe, podatkowe lub reklamowe (tego rodzaju koszty pokrywane są w ramach kosztów pośrednich (ogólnych)). Limit na podwykonawstwo, tzn. wartość prac realizowanych na zasadzie podwykonawstwa nie może przekroczyć: - 50% kosztów kwalifikowalnych badań przemysłowych i prac rozwojowych ponoszonych w module przez dane przedsiębiorstwo; - 25% kosztów kwalifikowalnych badań przemysłowych i eksperymentalnych prac rozwojowych ponoszonych w module przez organizację badawczą. Koszty usług zewnętrznych (podwykonawstwa) nie zaliczają się do podstawy naliczania kosztów pośrednich modułu. W ramach kategorii podwykonawstwo kwalifikowalne są umowy o dzieło oraz umowy B2B.
B29: Lp. | C29: Nazwa wydatku | D29: Wydatki ogółem | E29: Wydatki kwalifikowalne | F29: VAT | G29: Dofinansowanie | H29: Uzasadnienie kosztu max. 1500 znaków | I29: Metody szacowania max. 1500 znaków
B30: 1 | C30: Koszt usług ... (zadanie 1) | D30: 0 | E30: 0 | F30: =D30-E30 -> 0 | G30: =E30*80% -> 0
B31: SUMA USŁUGI ZEWNĘTRZNE: | D31: =SUM(D30) -> 0 | E31: =SUM(E30) -> 0 | F31: =SUM(F30) -> 0 | G31: =SUM(G30) -> 0
B32: Amortyzacja (aparatura i sprzęt, budynki, nieruchomości [w odniesieniu do nieruchomości - wyłącznie raty czynszu dzierżawnego lub opłaty za użytkowanie wieczyste])
B33: W ramach kategorii kwalifikowalne są odpisy amortyzacyjne aparatury naukowo-badawczej i sprzętu wykorzystywanych w celu prowadzenia badań przemysłowych i prac rozwojowych albo tylko prac rozwojowych wyłącznie w zakresie i przez okres, w jakim są one wykorzystywane na potrzeby realizowanego modułu B+R.
B34: Lp. | C34: Nazwa wydatku | D34: Wydatki ogółem | E34: Wydatki kwalifikowalne | F34: VAT | G34: Dofinansowanie | H34: Uzasadnienie kosztu max. 1500 znaków | I34: Metody szacowania max. 1500 znaków
C35: Jednorazowa amortyzacja kosztu zakupu sprzętu komputerowego (4 szt. komputerów) | D35: 0 | E35: 0 | F35: =D35-E35 -> 0 | G35: =E35*80% -> 0 | H35: Prykładowy opis: Zakup niezbędnych komputerów planowanych do wykorzystywania podczas realizacji zadań w projekcie. Uzasadnienie: konieczność raportowania wyników badań, przeprowadzania analiz. | I35: Przykładowy opis: Rozeznanie rynku na podstawie ogólnodostępnych cenników internetowych na stronach MediaExpert, Dell24, DIGITMEDIA, MediaMarkt. Na podstawie posiadanych cen koszt został uśredniony.
C36: Odpisy amortyzacyjne aparatury naukowo-badawczej i sprzętu (zadanie 1) | D36: 0 | E36: 0 | F36: =D36-E36 -> 0 | G36: =E36*80% -> 0 | K36: uzupełnic wartośc aktywów w zależnosci od limitu znaków; w uzasadnieniu jest jeszcze 600 znaków do wprowadzenia, w metodzie szacowania 200 | M36: =LEN(H36) -> 0
B37: 1 | C37: Odpisy amortyzacyjne aparatury naukowo-badawczej i sprzętu (zadanie 1) - ciąg dalszy 1 | D37: 0 | E37: 0 | F37: =D37-E37 -> 0 | G37: =(E37*80%) -> 0 | K37: uzupełnic wartośc aktywów w zależnosci od limitu znaków. w uzasadnieniu jest jeszcze 550 znaków do wprowadzenia, w metodzie szacowania 200 | M37: =LEN(H37) -> 0
B38: SUMA AMORTYZACJA: | D38: =SUM(D35:D37) -> 0 | E38: =SUM(E35:E37) -> 0 | F38: =SUM(F35:F37) -> 0 | G38: =SUM(G35:G37) -> 0
B39: Wartości niematerialne i prawne
B40: Dla lidera konsorcjum lub członków konsorcjum w ramach kategorii kwalifikowalne są koszty nabycia wartości niematerialnych i prawnych nabytych od osób trzecich na warunkach rynkowych – w formie patentów zakupionych lub użytkowanych na podstawie licencji, know-how, nieopatentowanej wiedzy technicznej, ekspertyz, analiz, raportów badawczych itp., wykorzystywanych, aby prowadzić badania przemysłowe lub prace rozwojowe.
B41: 1 | C41: Zakup niezbędnych licencji na oprogramowanie specjalistyczne dla 4 szt. komputerów | F41: =D41-E41 -> 0 | G41: =E41*80% -> 0
B42: SUMA WARTOŚCI NIEMATERIALNE I PRAWNE: | D42: =SUM(D41) -> 0 | E42: =SUM(E41) -> 0 | F42: =SUM(F41) -> 0 | G42: =SUM(G41) -> 0
B43: Dostawy (inne niż środki trwałe)
B44: Kwalifikowalne są koszty: a) materiałów i środków eksploatacyjnych niezbędnych do realizacji prac B+R np. koszty surowców, półproduktów, odczynników; b) sprzętu laboratoryjnego wykorzystywanego do prac B+R, tj. koszty zakupów, które nie są środkiem trwałym zgodnie z ustawą o rachunkowości oraz z polityką rachunkowości lidera konsorcjum lub członka konsorcjum; c) utrzymania linii technologicznych, instalacji doświadczalnych itp. w okresie i w proporcji, w jakiej są wykorzystywane do prac B+R; d) eksploatacji aparatury naukowo-badawczej; e) zakupu elementów służących do budowy prototypu i na stałe zainstalowanych w prototypie, instalacji pilotażowej lub demonstracyjnej.
...

Sheet BUDŻET - zad. 2
B2: BUDŻET
B3: Dofinansowanie w projektach będzie miało charakter dotacji i będzie udzielane w formie pomocy publicznej i pomocy de minimis dla lidera konsorcjum oraz pozostałych konsorcjantów niebędących organizacją badawczą. Minimalna wysokość wydatków kwalifikowalnych wynosi 3 mln zł. Łączna kwota wnioskowanego dofinansowania nie może przekroczyć 140 mln zł na cały projekt. Organizacje badawcze w ramach swojej działalności niegospodarczej uzyskują wsparcie bez pomocy publicznej.
B7: Tytuł zadania:
B8: Zadanie 2
B9: Wynagrodzenia - Personel projektu
B10: W ramach kategorii kwalifikowalne jest wyłącznie wynagrodzenie personelu projektu badawczo-rozwojowego będącego przedmiotem modułu B+R - pracowników kadry naukowo-badawczej W przypadku wykonywania przez dany personel jakichkolwiek zadań związanych z zarządzaniem, nadzorem lub koordynacją projektem badawczo-rozwojowym będącym przedmiotem modułu B+R lub zarządzeniem modułem B+R lub zarządzaniem projektem (składającym się także z innych modułów niż moduł B+R), koszt jego wynagrodzenia jest niekwalifikowalny w kategorii Personel projektu. Koszt wynagrodzenia takich osób (np. kierownika zarządzającego modułem, kierownika modułu B+R), niezależnie od wymiaru zaangażowania w czynności zarządcze i łączenie ich z zadaniami badawczymi, stanowi w całości wydatek kwalifikowalny w kategorii Koszty pośrednie (ogólne).
B11: Lp. | C11: Nazwa wydatku | D11: Nazwa wydatku | E11: Wydatki kwalifikowalne | F11: VAT | G11: Dofinansowanie | H11: Uzasadnienie kosztu max. 1500 znaków | I11: Metody szacowania max. 1500 znaków
B12: 1 | F12: 0 | G12: =E12*80% -> 0 | H12: zgodnie z Przewodnikiem kwalifikowalności wydatków należy wskazać sposób zaangażowania pracownika np.. Umowa o pracę, kontrakt B2B, dodatki zadaniowe, oddelegowanie, umowy zlecenia). Kwoty należy podać jako pełny koszt (tzw. brutto brutto) z uwzględnieniem wynagrodzenia zasadnicznego + składek po stronie pracownika i pracodwacy wraz z okresem zaangażowania pracownika do realizacji zadania (wymiar etatu, zaangażowanie godzinowe), należy pokazać kalkulację wydatku projektowego. Łączne zaangażowanie zawodowe personelu projektu w realizację wszystkich projektów finansowanych z funduszy UE oraz działań finansowanych z innych źródeł, w tym środków własnych lidera konsorcjum lub konsorcjanta i innych podmiotów (niezależnie od formy zaangażowania) nie przekracza 276 godzin miesięcznie | K12: Podatek VAT co do zasady stanowi wydatek niekwalifikowalny w projekcie. Podatek VAT może stanowić wydatek kwalifikowalny dla danego członka konsorcjum w ramach projektu tylko wtedy, gdy danemu członkowi konsorcjum, zgodnie z obowiązującym prawodawstwem krajowym, nie przysługuje prawo do obniżenia kwoty podatku należnego o kwotę podatku naliczonego lub ubiegania się o zwrot podatku VAT. Posiadanie przez danego członka konsorcjum wyżej wymienionego prawa (potencjalnej prawnej możliwości) wyklucza uznanie wydatku za kwalifikowalny, nawet jeśli faktycznie zwrot nie nastąpił, np. ze względu na niepodjęcie przez danego członka konsorcjum czynności zmierzających do realizacji tego prawa. Ocena kwalifikowalności VAT jest dokonywana z punktu widzenia każdego z członków konsorcjum z osobna – z uwzględnieniem ich prawa do odzyskania VAT. Dla projektów z planowaną komercjalizacją rozumianą jako przychód zalecaną formą jest wybór VAT jak kosztu niekwalifikowalnego, niemniej jednak decyzja w tym zakresie leży po stronie danego podmiotu będącego członkiem konsorcjum.
B13: 2 | F13: 0 | G13: =E13*80% -> 0
B14: 3 | F14: 0 | G14: =E14*80% -> 0
B15: 4 | F15: 0 | G15: =E15*80% -> 0
B16: 5 | F16: 0 | G16: =E16*80% -> 0
B17: 6 | F17: 0 | G17: =E17*80% -> 0
B18: 7 | F18: 0 | G18: =E18*80% -> 0
B19: 8 | F19: 0 | G19: =E19*80% -> 0
B20: 9 | F20: 0 | G20: =E20*80% -> 0
B21: 10 | F21: 0 | G21: =E21*80% -> 0
B22: SUMA WYNAGRODZENIA: | D22: =SUM(D7:D21) -> 0 | E22: =SUM(E7:E21) -> 0 | F22: =SUM(F7:F18) -> 0 | G22: =SUM(G12:G21) -> 0
B23: Usługi zewnętrzne (podwykonawstwo)
B24: W ramach kategorii usługi zewnętrzne (podwykonawstwo) kwalifikowalne są koszty badań wykonywanych na podstawie umowy oraz koszty doradztwa i równorzędnych usług wykorzystywanych wyłącznie na potrzeby projektu badawczo-rozwojowego. Podwykonawstwem nie są czynności pomocnicze niezbędne do wykonania zadań projektowych, takie jak usługi prawne, księgowe, podatkowe lub reklamowe (tego rodzaju koszty pokrywane są w ramach kosztów pośrednich (ogólnych)). Limit na podwykonawstwo, tzn. wartość prac realizowanych na zasadzie podwykonawstwa nie może przekroczyć: - 50% kosztów kwalifikowalnych badań przemysłowych i prac rozwojowych ponoszonych w module przez dane przedsiębiorstwo; - 25% kosztów kwalifikowalnych badań przemysłowych i eksperymentalnych prac rozwojowych ponoszonych w module przez organizację badawczą. Koszty usług zewnętrznych (podwykonawstwa) nie zaliczają się do podstawy naliczania kosztów pośrednich modułu. W ramach kategorii podwykonawstwo kwalifikowalne są umowy o dzieło oraz umowy B2B.
B25: Lp. | C25: Nazwa wydatku | D25: Wydatki ogółem | E25: Wydatki kwalifikowalne | F25: VAT | G25: Dofinansowanie | H25: Uzasadnienie kosztu | I25: Metody szacowania
B26: 1 | C26: Nie dotyczy | D26: 0 | E26: 0 | F26: 0 | G26: =E26*80% -> 0 | H26: 0 | I26: 0
B27: SUMA USŁUGI ZEWNĘTRZNE: | D27: =SUM(D26) -> 0 | E27: =SUM(E26) -> 0 | F27: =SUM(F26) -> 0 | G27: =SUM(G26) -> 0
B28: Amortyzacja (aparatura i sprzęt, budynki, nieruchomości [w odniesieniu do nieruchomości - wyłącznie raty czynszu dzierżawnego lub opłaty za użytkowanie wieczyste])
B29: W ramach kategorii kwalifikowalne są odpisy amortyzacyjne aparatury naukowo-badawczej i sprzętu wykorzystywanych w celu prowadzenia badań przemysłowych i prac rozwojowych albo tylko prac rozwojowych wyłącznie w zakresie i przez okres, w jakim są one wykorzystywane na potrzeby realizowanego modułu B+R.
B30: Lp. | C30: Nazwa wydatku | D30: Wydatki ogółem | E30: Wydatki kwalifikowalne | F30: VAT | G30: Dofinansowanie | H30: Uzasadnienie kosztu max. 1500 znaków | I30: Metody szacowania max. 1500 znaków
B31: 1 | C31: Jednorazowa amortyzacja kosztu zakupu sprzętu komputerowego (4 szt. komputerów) | D31: 0 | E31: =D31-F31 -> 0 | F31: 0 | G31: =E31*80% -> 0 | H31: Prykładowy opis: Zakup niezbędnych komputerów planowanych do wykorzystywania podczas realizacji zadań w projekcie. Uzasadnienie: konieczność raportowania wyników badań, przeprowadzania analiz. | I31: Przykładowy opis: Rozeznanie rynku na podstawie ogólnodostępnych cenników internetowych na stronach MediaExpert, Dell24, DIGITMEDIA, MediaMarkt. Na podstawie posiadanych cen koszt został uśredniony.
B32: SUMA AMORTYZACJA: | D32: =SUM(D31) -> 0 | E32: =SUM(E31) -> 0 | F32: =SUM(F31) -> 0 | G32: =SUM(G31) -> 0
B33: Wartości niematerialne i prawne
B34: Dla lidera konsorcjum lub członków konsorcjum w ramach kategorii kwalifikowalne są koszty nabycia wartości niematerialnych i prawnych nabytych od osób trzecich na warunkach rynkowych – w formie patentów zakupionych lub użytkowanych na podstawie licencji, know-how, nieopatentowanej wiedzy technicznej, ekspertyz, analiz, raportów badawczych itp., wykorzystywanych, aby prowadzić badania przemysłowe lub prace rozwojowe.
B35: 1 | C35: Zakup niezbędnych licencji na oprogramowanie specjalistyczne dla 4 szt. komputerów | D35: 0 | E35: =D35-F35 -> 0 | F35: 0 | G35: =E35*80% -> 0 | H35: Zakup niezbędnych licencji na oprogramowanie specjalistyczne do komputerów planowanych do wykorzystywania podczas prowadzenia badań przemysłowych w projekcie. Uzasadnienie: konieczność raportowania wyników badań, przeprowadzania analiz.Liczba planowanych do zakupu licencji na oprogramowanie specjalistyczne odpowiada liczbie pracowników, którzy wejdą w skład zespołu projektowego. | I35: Rozeznanie rynku na podstawie ogólnodostępnych cenników internetowych. Uwzględniono konieczność zakupu licencji dla kilku programów, uśredniono wartość. Licencja program EndNote do opracowywania bibliografii, cennik: https://endnote.com/buy/, program Refworks, cennik: https://www.refworks.io/pricing Pakiet Office: https://www.microsoft.com/pl-PL/microsoft-365/p/office-professional-2021/CFQ7TTC0HHJ9?activetab=pivot:informacjeog%C3%B3lnetab
B36: SUMA WARTOŚCI NIEMATERIALNE I PRAWNE: | D36: =SUM(D35) -> 0 | E36: =SUM(E35) -> 0 | F36: =SUM(F35) -> 0 | G36: =SUM(G35) -> 0
B37: Dostawy (inne niż środki trwałe)
B38: Kwalifikowalne są koszty: a) materiałów i środków eksploatacyjnych niezbędnych do realizacji prac B+R np. koszty surowców, półproduktów, odczynników; b) sprzętu laboratoryjnego wykorzystywanego do prac B+R, tj. koszty zakupów, które nie są środkiem trwałym zgodnie z ustawą o rachunkowości oraz z polityką rachunkowości lidera konsorcjum lub członka konsorcjum; c) utrzymania linii technologicznych, instalacji doświadczalnych itp. w okresie i w proporcji, w jakiej są wykorzystywane do prac B+R; d) eksploatacji aparatury naukowo-badawczej; e) zakupu elementów służących do budowy prototypu i na stałe zainstalowanych w prototypie, instalacji pilotażowej lub demonstracyjnej.
B39: Lp. | C39: Nazwa wydatku | D39: Wydatki ogółem | E39: Wydatki kwalifikowalne | F39: VAT | G39: Dofinansowanie | H39: Uzasadnienie kosztu max. 1500 znaków | I39: Metody szacowania max. 1500 znaków
B40: 1 | D40: 0 | E40: =D40-F40 -> 0 | F40: 0 | G40: =E40*80% -> 0
B41: 2 | D41: 0 | E41: =D41-F41 -> 0 | F41: 0 | G41: =E41*80% -> 0
B42: 3 | D42: 0 | E42: =D42-F42 -> 0 | F42: 0 | G42: =E42*80% -> 0
B43: 5 | D43: 0 | E43: =D43-F43 -> 0 | F43: 0 | G43: =E43*80% -> 0
B44: 6 | D44: 0 | E44: =D44-F44 -> 0 | F44: 0 | G44: =E44*80% -> 0
...

Sheet BUDŻET - zad. 3
B2: BUDŻET
B3: Dofinansowanie w projektach będzie miało charakter dotacji i będzie udzielane w formie pomocy publicznej i pomocy de minimis dla lidera konsorcjum oraz pozostałych konsorcjantów niebędących organizacją badawczą. Minimalna wysokość wydatków kwalifikowalnych wynosi 3 mln zł. Łączna kwota wnioskowanego dofinansowania nie może przekroczyć 140 mln zł na cały projekt. Organizacje badawcze w ramach swojej działalności niegospodarczej uzyskują wsparcie bez pomocy publicznej.
B7: Tytuł zadania:
B8: Zadanie 4
B9: Wynagrodzenia - Personel projektu
B10: W ramach kategorii kwalifikowalne jest wyłącznie wynagrodzenie personelu projektu badawczo-rozwojowego będącego przedmiotem modułu B+R - pracowników kadry naukowo-badawczej W przypadku wykonywania przez dany personel jakichkolwiek zadań związanych z zarządzaniem, nadzorem lub koordynacją projektem badawczo-rozwojowym będącym przedmiotem modułu B+R lub zarządzeniem modułem B+R lub zarządzaniem projektem (składającym się także z innych modułów niż moduł B+R), koszt jego wynagrodzenia jest niekwalifikowalny w kategorii Personel projektu. Koszt wynagrodzenia takich osób (np. kierownika zarządzającego modułem, kierownika modułu B+R), niezależnie od wymiaru zaangażowania w czynności zarządcze i łączenie ich z zadaniami badawczymi, stanowi w całości wydatek kwalifikowalny w kategorii Koszty pośrednie (ogólne).
B11: Lp. | C11: Nazwa wydatku | D11: Wydatki ogółem | E11: Wydatki kwalifikowalne | F11: VAT | G11: Dofinansowanie | H11: Uzasadnienie kosztu max. 1500 znaków | I11: Metody szacowania max. 1500 znaków
B12: 1 | D12: 0 | E12: =D12-F12 -> 0 | F12: 0 | G12: =E12*80% -> 0 | K12: Podatek VAT co do zasady stanowi wydatek niekwalifikowalny w projekcie. Podatek VAT może stanowić wydatek kwalifikowalny dla danego członka konsorcjum w ramach projektu tylko wtedy, gdy danemu członkowi konsorcjum, zgodnie z obowiązującym prawodawstwem krajowym, nie przysługuje prawo do obniżenia kwoty podatku należnego o kwotę podatku naliczonego lub ubiegania się o zwrot podatku VAT. Posiadanie przez danego członka konsorcjum wyżej wymienionego prawa (potencjalnej prawnej możliwości) wyklucza uznanie wydatku za kwalifikowalny, nawet jeśli faktycznie zwrot nie nastąpił, np. ze względu na niepodjęcie przez danego członka konsorcjum czynności zmierzających do realizacji tego prawa. Ocena kwalifikowalności VAT jest dokonywana z punktu widzenia każdego z członków konsorcjum z osobna – z uwzględnieniem ich prawa do odzyskania VAT. Dla projektów z planowaną komercjalizacją rozumianą jako przychód zalecaną formą jest wybór VAT jak kosztu niekwalifikowalnego, niemniej jednak decyzja w tym zakresie leży po stronie danego podmiotu będącego członkiem konsorcjum.
B13: 2 | D13: 0 | E13: =D13-F13 -> 0 | F13: 0 | G13: =E13*80% -> 0
B14: 3 | D14: 0 | E14: =D14-F14 -> 0 | F14: 0 | G14: =E14*80% -> 0
B15: 4 | D15: 0 | E15: =D15-F15 -> 0 | F15: 0 | G15: =E15*80% -> 0
B16: 5 | D16: 0 | E16: =D16-F16 -> 0 | F16: 0 | G16: =E16*80% -> 0
B17: 6 | D17: 0 | E17: =D17-F17 -> 0 | F17: 0 | G17: =E17*80% -> 0
B18: 7 | D18: 0 | E18: =D18-F18 -> 0 | F18: 0 | G18: =E18*80% -> 0
B19: 8 | D19: 0 | E19: =D19-F19 -> 0 | F19: 0 | G19: =E19*80% -> 0
B20: 9 | D20: 0 | E20: =D20-F20 -> 0 | F20: 0 | G20: =E20*80% -> 0
B21: 9 | D21: 0 | E21: =D21-F21 -> 0 | F21: 0 | G21: =E21*80% -> 0
B22: 10 | D22: 0 | E22: =D22-F22 -> 0 | F22: 0 | G22: =E22*80% -> 0
B23: 11 | D23: 0 | E23: =D23-F23 -> 0 | F23: 0 | G23: =E23*80% -> 0
B24: SUMA WYNAGRODZENIA: | D24: =SUM(D12:D23) -> 0 | E24: =SUM(E12:E23) -> 0 | F24: =SUM(F12:F23) -> 0 | G24: =SUM(G12:G23) -> 0
B25: Usługi zewnętrzne (podwykonawstwo)
B26: W ramach kategorii usługi zewnętrzne (podwykonawstwo) kwalifikowalne są koszty badań wykonywanych na podstawie umowy oraz koszty doradztwa i równorzędnych usług wykorzystywanych wyłącznie na potrzeby projektu badawczo-rozwojowego. Podwykonawstwem nie są czynności pomocnicze niezbędne do wykonania zadań projektowych, takie jak usługi prawne, księgowe, podatkowe lub reklamowe (tego rodzaju koszty pokrywane są w ramach kosztów pośrednich (ogólnych)). Limit na podwykonawstwo, tzn. wartość prac realizowanych na zasadzie podwykonawstwa nie może przekroczyć: - 50% kosztów kwalifikowalnych badań przemysłowych i prac rozwojowych ponoszonych w module przez dane przedsiębiorstwo; - 25% kosztów kwalifikowalnych badań przemysłowych i eksperymentalnych prac rozwojowych ponoszonych w module przez organizację badawczą. Koszty usług zewnętrznych (podwykonawstwa) nie zaliczają się do podstawy naliczania kosztów pośrednich modułu. W ramach kategorii podwykonawstwo kwalifikowalne są umowy o dzieło oraz umowy B2B.
B27: Lp. | C27: Nazwa wydatku | D27: Wydatki ogółem | E27: Wydatki kwalifikowalne | F27: VAT | G27: Dofinansowanie | H27: Uzasadnienie kosztu max. 1500 znaków | I27: Metody szacowania max. 1500 znaków
B28: 1 | D28: 0 | E28: =D28-F28 -> 0 | F28: 0 | G28: =E28*80% -> 0
B29: SUMA USŁUGI ZEWNĘTRZNE: | D29: =SUM(D28) -> 0 | E29: =SUM(E28) -> 0 | F29: =SUM(F28) -> 0 | G29: =SUM(G28) -> 0
B30: Amortyzacja (aparatura i sprzęt, budynki, nieruchomości [w odniesieniu do nieruchomości - wyłącznie raty czynszu dzierżawnego lub opłaty za użytkowanie wieczyste])
B31: W ramach kategorii kwalifikowalne są odpisy amortyzacyjne aparatury naukowo-badawczej i sprzętu wykorzystywanych w celu prowadzenia badań przemysłowych i prac rozwojowych albo tylko prac rozwojowych wyłącznie w zakresie i przez okres, w jakim są one wykorzystywane na potrzeby realizowanego modułu B+R.
B32: Lp. | C32: Nazwa wydatku | D32: Wydatki ogółem | E32: Wydatki kwalifikowalne | F32: VAT | G32: Dofinansowanie | H32: Uzasadnienie kosztu max. 1500 znaków | I32: Metody szacowania max. 1500 znaków
B33: 1 | D33: 0 | E33: =D33-F33 -> 0 | F33: 0 | G33: =(E33*80%) -> 0 | J33: =LEN(H33) -> 0 | K33: =LEN(I33) -> 0
B34: 2 | D34: 0 | E34: =D34-F34 -> 0 | F34: 0 | G34: =(E34*80%) -> 0 | J34: =LEN(H34) -> 0 | K34: =LEN(I34) -> 0
B35: SUMA AMORTYZACJA: | D35: =SUM(D33:D34) -> 0 | E35: =SUM(E33:E34) -> 0 | F35: =SUM(F34) -> 0 | G35: =SUM(G33:G34) -> 0
B36: Wartości niematerialne i prawne
B37: Dla lidera konsorcjum lub członków konsorcjum w ramach kategorii kwalifikowalne są koszty nabycia wartości niematerialnych i prawnych nabytych od osób trzecich na warunkach rynkowych – w formie patentów zakupionych lub użytkowanych na podstawie licencji, know-how, nieopatentowanej wiedzy technicznej, ekspertyz, analiz, raportów badawczych itp., wykorzystywanych, aby prowadzić badania przemysłowe lub prace rozwojowe.
B38: 1 | C38: Nie dotyczy | D38: 0 | E38: 0 | F38: 0 | G38: 0 | H38: - | I38: -
B39: SUMA WARTOŚCI NIEMATERIALNE I PRAWNE: | D39: =SUM(D38) -> 0 | E39: =SUM(E38) -> 0 | F39: =SUM(F38) -> 0 | G39: =SUM(G38) -> 0
B40: Dostawy (inne niż środki trwałe)
B41: Kwalifikowalne są koszty: a) materiałów i środków eksploatacyjnych niezbędnych do realizacji prac B+R np. koszty surowców, półproduktów, odczynników; b) sprzętu laboratoryjnego wykorzystywanego do prac B+R, tj. koszty zakupów, które nie są środkiem trwałym zgodnie z ustawą o rachunkowości oraz z polityką rachunkowości lidera konsorcjum lub członka konsorcjum; c) utrzymania linii technologicznych, instalacji doświadczalnych itp. w okresie i w proporcji, w jakiej są wykorzystywane do prac B+R; d) eksploatacji aparatury naukowo-badawczej; e) zakupu elementów służących do budowy prototypu i na stałe zainstalowanych w prototypie, instalacji pilotażowej lub demonstracyjnej.
B42: Lp. | C42: Nazwa wydatku | D42: Wydatki ogółem | E42: Wydatki kwalifikowalne | F42: VAT | G42: Dofinansowanie | H42: Uzasadnienie kosztu max. 1500 znaków | I42: Metody szacowania max. 1500 znaków
B43: 1 | D43: 0 | E43: =D43-F43 -> 0 | F43: 0 | G43: =E43*80% -> 0 | J43: =LEN(H43) -> 0 | K43: =LEN(I43) -> 0
B44: 2 | D44: 0 | E44: =D44-F44 -> 0 | F44: 0 | G44: =E44*80% -> 0 | J44: =LEN(H44) -> 0 | K44: =LEN(I44) -> 0
...

Sheet BUDŻET - zad. 4
B2: BUDŻET
B3: Dofinansowanie w projektach będzie miało charakter dotacji i będzie udzielane w formie pomocy publicznej i pomocy de minimis dla lidera konsorcjum oraz pozostałych konsorcjantów niebędących organizacją badawczą. Minimalna wysokość wydatków kwalifikowalnych wynosi 3 mln zł. Łączna kwota wnioskowanego dofinansowania nie może przekroczyć 140 mln zł na cały projekt. Organizacje badawcze w ramach swojej działalności niegospodarczej uzyskują wsparcie bez pomocy publicznej.
B7: Tytuł zadania:
B8: Zadanie 4
B9: Wynagrodzenia - Personel projektu
B10: W ramach kategorii kwalifikowalne jest wyłącznie wynagrodzenie personelu projektu badawczo-rozwojowego będącego przedmiotem modułu B+R - pracowników kadry naukowo-badawczej W przypadku wykonywania przez dany personel jakichkolwiek zadań związanych z zarządzaniem, nadzorem lub koordynacją projektem badawczo-rozwojowym będącym przedmiotem modułu B+R lub zarządzeniem modułem B+R lub zarządzaniem projektem (składającym się także z innych modułów niż moduł B+R), koszt jego wynagrodzenia jest niekwalifikowalny w kategorii Personel projektu. Koszt wynagrodzenia takich osób (np. kierownika zarządzającego modułem, kierownika modułu B+R), niezależnie od wymiaru zaangażowania w czynności zarządcze i łączenie ich z zadaniami badawczymi, stanowi w całości wydatek kwalifikowalny w kategorii Koszty pośrednie (ogólne).
B11: Lp. | C11: Nazwa wydatku | D11: Wydatki ogółem | E11: Wydatki kwalifikowalne | F11: VAT | G11: Dofinansowanie | H11: Uzasadnienie kosztu max. 1500 znaków | I11: Metody szacowania max. 1500 znaków
B12: 1 | D12: 0 | E12: =D12-F12 -> 0 | F12: 0 | G12: =E12*60% -> 0 | K12: Podatek VAT co do zasady stanowi wydatek niekwalifikowalny w projekcie. Podatek VAT może stanowić wydatek kwalifikowalny dla danego członka konsorcjum w ramach projektu tylko wtedy, gdy danemu członkowi konsorcjum, zgodnie z obowiązującym prawodawstwem krajowym, nie przysługuje prawo do obniżenia kwoty podatku należnego o kwotę podatku naliczonego lub ubiegania się o zwrot podatku VAT. Posiadanie przez danego członka konsorcjum wyżej wymienionego prawa (potencjalnej prawnej możliwości) wyklucza uznanie wydatku za kwalifikowalny, nawet jeśli faktycznie zwrot nie nastąpił, np. ze względu na niepodjęcie przez danego członka konsorcjum czynności zmierzających do realizacji tego prawa. Ocena kwalifikowalności VAT jest dokonywana z punktu widzenia każdego z członków konsorcjum z osobna – z uwzględnieniem ich prawa do odzyskania VAT. Dla projektów z planowaną komercjalizacją rozumianą jako przychód zalecaną formą jest wybór VAT jak kosztu niekwalifikowalnego, niemniej jednak decyzja w tym zakresie leży po stronie danego podmiotu będącego członkiem konsorcjum.
B13: 2 | D13: 0 | E13: =D13-F13 -> 0 | F13: 0 | G13: =E13*60% -> 0
B14: 3 | D14: 0 | E14: =D14-F14 -> 0 | F14: 0 | G14: =E14*60% -> 0
B15: 4 | D15: 0 | E15: =D15-F15 -> 0 | F15: 0 | G15: =E15*60% -> 0
B16: 5 | D16: 0 | E16: =D16-F16 -> 0 | F16: 0 | G16: =E16*60% -> 0
B17: 6 | D17: 0 | E17: =D17-F17 -> 0 | F17: 0 | G17: =E17*60% -> 0
B18: SUMA WYNAGRODZENIA: | D18: =SUM(D12:D17) -> 0 | E18: =SUM(E12:E17) -> 0 | F18: =SUM(F12:F17) -> 0 | G18: =SUM(G12:G17) -> 0
B19: Usługi zewnętrzne (podwykonawstwo)
B20: W ramach kategorii usługi zewnętrzne (podwykonawstwo) kwalifikowalne są koszty badań wykonywanych na podstawie umowy oraz koszty doradztwa i równorzędnych usług wykorzystywanych wyłącznie na potrzeby projektu badawczo-rozwojowego. Podwykonawstwem nie są czynności pomocnicze niezbędne do wykonania zadań projektowych, takie jak usługi prawne, księgowe, podatkowe lub reklamowe (tego rodzaju koszty pokrywane są w ramach kosztów pośrednich (ogólnych)). Limit na podwykonawstwo, tzn. wartość prac realizowanych na zasadzie podwykonawstwa nie może przekroczyć: - 50% kosztów kwalifikowalnych badań przemysłowych i prac rozwojowych ponoszonych w module przez dane przedsiębiorstwo; - 25% kosztów kwalifikowalnych badań przemysłowych i eksperymentalnych prac rozwojowych ponoszonych w module przez organizację badawczą. Koszty usług zewnętrznych (podwykonawstwa) nie zaliczają się do podstawy naliczania kosztów pośrednich modułu. W ramach kategorii podwykonawstwo kwalifikowalne są umowy o dzieło oraz umowy B2B.
B21: Lp. | C21: Nazwa wydatku | D21: Wydatki ogółem | E21: Wydatki kwalifikowalne | F21: VAT | G21: Dofinansowanie | H21: Uzasadnienie kosztu max. 1500 znaków | I21: Metody szacowania max. 1500 znaków
B22: 1 | D22: 0 | E22: =D22-F22 -> 0 | F22: 0 | G22: =E22*60% -> 0
B23: SUMA USŁUGI ZEWNĘTRZNE: | D23: =SUM(D22) -> 0 | E23: =SUM(E22) -> 0 | F23: =SUM(F22) -> 0 | G23: =SUM(G22) -> 0
B24: Amortyzacja (aparatura i sprzęt, budynki, nieruchomości [w odniesieniu do nieruchomości - wyłącznie raty czynszu dzierżawnego lub opłaty za użytkowanie wieczyste])
B25: W ramach kategorii kwalifikowalne są odpisy amortyzacyjne aparatury naukowo-badawczej i sprzętu wykorzystywanych w celu prowadzenia badań przemysłowych i prac rozwojowych albo tylko prac rozwojowych wyłącznie w zakresie i przez okres, w jakim są one wykorzystywane na potrzeby realizowanego modułu B+R.
B26: Lp. | C26: Nazwa wydatku | D26: Wydatki ogółem | E26: Wydatki kwalifikowalne | F26: VAT | G26: Dofinansowanie | H26: Uzasadnienie kosztu | I26: Metody szacowania
B27: 1 | C27: Nie dotyczy | D27: 0 | E27: =D27-F27 -> 0 | F27: 0 | G27: =E27*60% -> 0 | H27: - | I27: -
B28: SUMA AMORTYZACJA: | D28: =SUM(D27) -> 0 | E28: =SUM(E27) -> 0 | F28: =SUM(F27) -> 0 | G28: =SUM(G27) -> 0
B29: Wartości niematerialne i prawne
B30: Dla lidera konsorcjum lub członków konsorcjum w ramach kategorii kwalifikowalne są koszty nabycia wartości niematerialnych i prawnych nabytych od osób trzecich na warunkach rynkowych – w formie patentów zakupionych lub użytkowanych na podstawie licencji, know-how, nieopatentowanej wiedzy technicznej, ekspertyz, analiz, raportów badawczych itp., wykorzystywanych, aby prowadzić badania przemysłowe lub prace rozwojowe.
B31: 1 | C31: Nie dotyczy | D31: 0 | E31: =D31-F31 -> 0 | F31: 0 | G31: =E31*60% -> 0 | H31: - | I31: -
B32: SUMA WARTOŚCI NIEMATERIALNE I PRAWNE: | D32: =SUM(D31) -> 0 | E32: =SUM(E31) -> 0 | F32: =SUM(F31) -> 0 | G32: =SUM(G31) -> 0
B33: Dostawy (inne niż środki trwałe)
B34: Kwalifikowalne są koszty: a) materiałów i środków eksploatacyjnych niezbędnych do realizacji prac B+R np. koszty surowców, półproduktów, odczynników; b) sprzętu laboratoryjnego wykorzystywanego do prac B+R, tj. koszty zakupów, które nie są środkiem trwałym zgodnie z ustawą o rachunkowości oraz z polityką rachunkowości lidera konsorcjum lub członka konsorcjum; c) utrzymania linii technologicznych, instalacji doświadczalnych itp. w okresie i w proporcji, w jakiej są wykorzystywane do prac B+R; d) eksploatacji aparatury naukowo-badawczej; e) zakupu elementów służących do budowy prototypu i na stałe zainstalowanych w prototypie, instalacji pilotażowej lub demonstracyjnej.
B35: Lp. | C35: Nazwa wydatku | D35: Wydatki ogółem | E35: Wydatki kwalifikowalne | F35: VAT | G35: Dofinansowanie | H35: Uzasadnienie kosztumax. 1500 znaków | I35: Metody szacowania max. 1500 znaków
B36: 1 | D36: 0 | E36: =D36-F36 -> 0 | F36: 0 | G36: =E36*60% -> 0 | L36: =LEN(H36) -> 0 | M36: =LEN(I36) -> 0
B37: 2 | D37: 0 | E37: =D37-F37 -> 0 | F37: 0 | G37: =E37*60% -> 0 | L37: =LEN(H37) -> 0 | M37: =LEN(I37) -> 0
B38: 3 | D38: 0 | E38: =D38-F38 -> 0 | F38: 0 | G38: =E38*60% -> 0 | L38: =LEN(H38) -> 0 | M38: =LEN(I38) -> 0
B39: 4 | D39: 0 | E39: =D39-F39 -> 0 | F39: 0 | G39: =E39*60% -> 0 | L39: =LEN(H39) -> 0 | M39: =LEN(I39) -> 0
B40: 5 | D40: 0 | E40: =D40-F40 -> 0 | F40: 0 | G40: =E40*60% -> 0 | L40: =LEN(H40) -> 0 | M40: =LEN(I40) -> 0
B41: 6 | D41: 0 | E41: =D41-F41 -> 0 | F41: 0 | G41: =E41*60% -> 0 | L41: =LEN(H41) -> 0 | M41: =LEN(I41) -> 0
B42: 7 | D42: 0 | E42: =D42-F42 -> 0 | F42: 0 | G42: =E42*60% -> 0 | L42: =LEN(H42) -> 0 | M42: =LEN(I42) -> 0
B43: 8 | D43: 0 | E43: =D43-F43 -> 0 | F43: 0 | G43: =E43*60% -> 0 | L43: =LEN(H43) -> 0 | M43: =LEN(I43) -> 0
B44: 9 | D44: 0 | E44: =D44-F44 -> 0 | F44: 0 | G44: =E44*60% -> 0 | L44: =LEN(H44) -> 0 | M44: =LEN(I44) -> 0
...

Sheet BUDŻET - KOSZTY POŚREDNIE
C1: SUMA WYDATKÓW BEZPOŚREDNICH (KWALIFIKOWALNE BEZ PODWYKONAWSTWA) | D1: PROCENT KOSZTÓW POŚREDNICH | E1: WARTOŚĆ CAŁKOWITA KOSZTÓW POŚREDNICH | F1: DOFINANSOWANIE KOSZTÓW POŚREDNICH
B2: UMW - bez pomocy publicznej | D2: 0.25 | E2: =C2*25% -> 0 | F2: =E2*100% -> 0 | H2: =E2=C2*25% -> TRUE | J2: Organizacja badawcza jako konsorcjant realizuje projekt w ramach swojej działalności niegospodarczej, w związku z tym udzielone dofinansowanie nie stanowi pomocy publicznej i może stanowić do 100% kosztów kwalifikowalnych. Może wziąć udział wyłącznie w realizacji prac B+R.
B3: Łukasiewicz – PORT - bez pomocy publicznej | E3: =C3*25% -> 0 | F3: =E3*100% -> 0 | H3: =E3=C3*25% -> TRUE
B4: Mentalicare - badania przemysłowe | E4: =C4*25% -> 0 | F4: =E4*80% -> 0 | H4: =E4=C4*25% -> TRUE | I4: ='BUDŻET - zad. 1'!D74+'BUDŻET - zad. 3'!D71 -> 0
B5: Mentalocare - prace rozwojowe | E5: =C5*25% -> 0 | F5: =E5*60% -> 0 | H5: =E5='BUDŻET - zad. 4'!D56 -> TRUE
B6: SUMA dla projektu | C6: =SUM(C2:C5) -> 0 | E6: =SUM(E2:E5) -> 0 | F6: =SUM(F2:F5) -> 0 | H6: =C6*25%=E6 -> TRUE
B8: Koszty pośrednie rozliczane są metodą ryczałtową i stanowią 25% kwalifikowalnych kosztów bezpośrednich dotyczących modułu B+R z wyjątkiem kosztów usług zewnętrznych (podwykonawstwo).
D13: ='BUDŻET - zad. 1'!D74 -> 0
D14: ='BUDŻET - zad. 3'!D71 -> 0

Sheet BUDŻET - SUMA
B1: Nr zadania | C1: Wydatki ogółem | D1: Wydatki kwalifikowalne | E1: VAT | F1: Dofinansowanie | G1: Wkład własny
B2: 1. | C2: ='BUDŻET - zad. 1'!D70 -> 0 | D2: ='BUDŻET - zad. 1'!E70 -> 0 | E2: ='BUDŻET - zad. 1'!F70 -> 0 | F2: ='BUDŻET - zad. 1'!G70 -> 0 | G2: ='BUDŻET - zad. 1'!D72 -> 0
B3: 2. | C3: ='BUDŻET - zad. 2'!D63 -> 0 | D3: ='BUDŻET - zad. 2'!E63 -> 0 | E3: ='BUDŻET - zad. 2'!F63 -> 0 | F3: ='BUDŻET - zad. 2'!G63 -> 0 | G3: ='BUDŻET - zad. 2'!D65 -> 0
B4: 3. | C4: ='BUDŻET - zad. 3'!D67 -> 0 | D4: ='BUDŻET - zad. 3'!E67 -> 0 | E4: ='BUDŻET - zad. 3'!F67 -> 0 | F4: ='BUDŻET - zad. 3'!G67 -> 0 | G4: ='BUDŻET - zad. 3'!D69 -> 0
B5: 4. | C5: ='BUDŻET - zad. 4'!D52 -> 0 | D5: ='BUDŻET - zad. 4'!E52 -> 0 | E5: ='BUDŻET - zad. 4'!F52 -> 0 | F5: ='BUDŻET - zad. 4'!G52 -> 0 | G5: ='BUDŻET - zad. 4'!D54 -> 0
B6: 5. | C6: ='BUDŻET - KOSZTY POŚREDNIE'!E6 -> 0 | D6: ='BUDŻET - KOSZTY POŚREDNIE'!E6 -> 0 | E6: =0 -> 0 | F6: ='BUDŻET - KOSZTY POŚREDNIE'!F6 -> 0 | G6: =C6-F6 -> 0
B8: SUMA dla projektu z pośrednimi: | C8: =SUM(C2:C6) -> 0 | D8: =SUM(D2:D6) -> 0 | E8: =SUM(E2:E6) -> 0 | F8: =SUM(F2:F6) -> 0 | G8: =SUM(G2:G6) -> 0
B9: SUMA dla projektu bez pośrednich: | C9: =SUM(C2:C5) -> 0 | D9: =SUM(D2:D5) -> 0 | E9: =SUM(E2:E5) -> 0 | F9: =SUM(F2:F5) -> 0 | G9: =SUM(G2:G5) -> 0
B11: UMW - koszty bezpośrednie
B12: UMW - koszty pośrednie
B13: UMW - CAŁOŚĆ
B15: Łukasiewicz – PORT - koszty bezpośrednie | I15: Budżet UMW/PORT musi stanowić co najmniej 10% całkowitych kosztów kwalifikowalnych projektu.
B16: Łukasiewicz – PORT - koszty pośrednie | I16: art. 25 Rozporządzenia 651/2014: "Projekt zakłada efektywną współpracę: — między przedsiębiorstwem i co najmniej jedną organizacją prowadzącą badania i upowszechniającą wiedzę, jeżeli ta ostatnia ponosi co najmniej 10 % kosztów kwalifikowalnych i ma prawo do publikowania własnych wyników badań."
B17: Łukasiewicz – PORT - CAŁOŚĆ | I17: Całkowite wydatki kwalifikowalne w projekcie:
I18: Wydatki kwalifikowalne UMW/Łukasiewicz – PORT:
B19: Lider - firma - koszty bezpośrednie | I19: Udział procentowy UMW/Łukasiewicz – PORT w wydatkach kwalifikowalnych projektu:
B20: Lider - firma - koszty pośrednie
B21: Lider - firma - CAŁOŚĆ
B23: Czy się zgadza? | C23: =C8=C17+C21 -> TRUE | D23: =D8=D17+D21 -> TRUE | E23: =E8=E15+E19 -> TRUE | F23: =F8=F17+F21 -> TRUE | G23: =G8=G15+G21 -> TRUE
B28: Limit na podwykonawstwo, tzn. wartość usług realizowanych na zasadzie podwykonawstwa nie może przekroczyć: - 50% kosztów kwalifikowalnych badań przemysłowych i prac rozwojowych ponoszonych w module przez dane przedsiębiorstwo - 25% kosztów kwalifikowalnych badań przemysłowych i eksperymentalnych prac rozwojowych ponoszonych w module przez organizację badawczą.
